Workbook

Sheet Client Info
A1: Client ID | B1: Business Type | C1: Name | D1: Address | E1: City | F1: Province | G1: PostalCode
A2: 10000 | B2: B2B - LPs | C2: Atlas Growers
A3: 20007 | B3: Provincial Distributor | C3: MBLL | D3: PO Box 1023 | E3: Winnipeg | F3: MB | G3: R3C2X1

Sheet productGTIN_internalSKU
A1: QA_product_name | B1: cannabislog_product_description | C1: cannabislog_stage | D1: product_description_stage | E1: canSKU_labelled | F1: canSKU_packaged | G1: canSKU_bulk_preroll | H1: canSKU_bulk
A2: Spa Bath Salts 180 g | B2: bath salt SPA 180 gram | C2: topical_labelled | D2: =B2&"_"&C2 -> bath salt SPA 180 gram_topical_labelled | E2: 13 | H2: 172
A3: CBD Bacon Oil 10 mg 27.3g | B3: CBD Bacon Oil 10 mg 27.3g | C3: extract_ingested_labelled | D3: =B3&"_"&C3 -> CBD Bacon Oil 10 mg 27.3g_extract_ingested_labelled | E3: 17
A4: Neem Cream 120 g | B4: CBD Neem Cream 120g | C4: extract_topical_labelled_RTV | D4: =B4&"_"&C4 -> CBD Neem Cream 120g_extract_topical_labelled_RTV | E4: 139
A5: Chronic Mint 1g | B5: Chronic Mint preroll 1 x 1g | C5: preroll_labelled | D5: =B5&"_"&C5 -> Chronic Mint preroll 1 x 1g_preroll_labelled | E5: 24 | H5: 25
A6: Chronic mint 3x0.5g preroll | B6: Chronic Mint preroll 3 x 0.5g | C6: preroll_labelled | D6: =B6&"_"&C6 -> Chronic Mint preroll 3 x 0.5g_preroll_labelled | E6: 26
A7: Extra Strength Roll-on Topical Cream | B7: Extra Strength Roll-on 88g | C7: topical_labelled | D7: =B7&"_"&C7 -> Extra Strength Roll-on 88g_topical_labelled | E7: 31
A8: Galactic cake 1 g preroll | B8: Galactic Cake preroll 1 x 1g | C8: preroll_labelled | D8: =B8&"_"&C8 -> Galactic Cake preroll 1 x 1g_preroll_labelled | E8: 34 | F8: 114 | H8: 35
A9: Galactic cake 3x0.5g preroll | B9: Galactic Cake preroll 3 x 0.5g | C9: preroll_labelled | D9: =B9&"_"&C9 -> Galactic Cake preroll 3 x 0.5g_preroll_labelled | E9: 36 | F9: 115
A10: Gelato 14 g | B10: Gelato dried flower 14g | C10: driedflower_labelled | D10: =B10&"_"&C10 -> Gelato dried flower 14g_driedflower_labelled | E10: 38 | F10: 116 | H10: 37
A11: Gelato Prerolls 1g | B11: Gelato preroll 1 x 1g | C11: preroll_labelled | D11: =B11&"_"&C11 -> Gelato preroll 1 x 1g_preroll_labelled | E11: 44 | H11: 45
A12: Gelato Prerolls 3x0.5g | B12: Gelato preroll 3 x 0.5g | C12: preroll_labelled | D12: =B12&"_"&C12 -> Gelato preroll 3 x 0.5g_preroll_labelled | E12: 46 | H12: 43
A13: Gorilla bomb 3x0.5g preroll | B13: Gorilla Bomb preroll 0.5g | C13: preroll_labelled | D13: =B13&"_"&C13 -> Gorilla Bomb preroll 0.5g_preroll_labelled | E13: 130 | F13: 52 | H13: 49
A14: Gorilla bomb 1 g preroll | B14: Gorilla Bomb preroll 1 x 1g | C14: preroll_labelled | D14: =B14&"_"&C14 -> Gorilla Bomb preroll 1 x 1g_preroll_labelled | E14: 50 | F14: 117 | H14: 51
A15: Grease monkey 1 g | B15: Grease Monkey preroll 1 x 1g | C15: preroll_labelled | D15: =B15&"_"&C15 -> Grease Monkey preroll 1 x 1g_preroll_labelled | E15: 57 | H15: 58
A16: Grease monkey 3x0.5 g | B16: Grease Monkey preroll 3 x 0.5g | C16: preroll_labelled | D16: =B16&"_"&C16 -> Grease Monkey preroll 3 x 0.5g_preroll_labelled | E16: 59 | F16: 119 | H16: 56

Sheet internal_cansku_inventory
A1: product_name | B1: product_description | C1: stage | D1: product_description_stage | E1: canSKU
B2: unknown dried flower | C2: driedflower_unknown | D2: =B2&"_"&C2 -> unknown dried flower_driedflower_unknown | E2: 1
B3: 20:1 Mango CBD:THC extract 29.5g | C3: extract_ingested_labelled | D3: =B3&"_"&C3 -> 20:1 Mango CBD:THC extract 29.5g_extract_ingested_labelled | E3: 2
B4: 4:1 Black Cherry CBD:THC extract 29.5g | C4: extract_ingested_labelled | D4: =B4&"_"&C4 -> 4:1 Black Cherry CBD:THC extract 29.5g_extract_ingested_labelled | E4: 3
B5: Abby Leaf Inc Licorish Gumball dried flower | C5: driedflower_bulk_BURB | D5: =B5&"_"&C5 -> Abby Leaf Inc Licorish Gumball dried flower_driedflower_bulk_BURB | E5: 4
B6: Abby Leaf Inc Unicorn Poop Grade | C6: driedflower_bulk_BURB | D6: =B6&"_"&C6 -> Abby Leaf Inc Unicorn Poop Grade _driedflower_bulk_BURB | E6: 5
B7: Animal Cookies dried flower 3.5 g | C7: driedflower_packaged | D7: =B7&"_"&C7 -> Animal Cookies dried flower 3.5 g_driedflower_packaged | E7: 6
B8: Aum CBD oil 27.4g | C8: extract_ingested_labelled | D8: =B8&"_"&C8 -> Aum CBD oil 27.4g_extract_ingested_labelled | E8: 7
B9: Backforty Blends Glacial Gold Clay Face Mask | C9: topical_labelled_RTV | D9: =B9&"_"&C9 -> Backforty Blends Glacial Gold Clay Face Mask_topical_labelled_RTV | E9: 8
B10: Bacon CBD Extract | C10: extract_ingested_bulk | D10: =B10&"_"&C10 -> Bacon CBD Extract_extract_ingested_bulk | E10: 9
B11: Bacon CBD Extract 27.6g | C11: extract_ingested_labelled | D11: =B11&"_"&C11 -> Bacon CBD Extract 27.6g_extract_ingested_labelled | E11: 10
B12: Bacon CBD extract 29.5g | C12: extract_ingested_labelled | D12: =B12&"_"&C12 -> Bacon CBD extract 29.5g_extract_ingested_labelled | E12: 11
B13: Bacon CBD extract 54.8g | C13: extract_ingested_labelled | D13: =B13&"_"&C13 -> Bacon CBD extract 54.8g_extract_ingested_labelled | E13: 12
I198: =C198&"_RTV" -> _RTV
I199: =C199&"_RTV" -> _RTV
I200: =C200&"_RTV" -> _RTV
I201: =C201&"_RTV" -> _RTV
I202: =C202&"_RTV" -> _RTV
I203: =C203&"_RTV" -> _RTV
I216: =C216&"_RTV" -> _RTV
I236: =C236&"_RTV" -> _RTV

Sheet Sheet1
A1: sales_stream | B1: Shipping date | C1: distributor_stream | D1: po_number | E1: level | K1: PO_date | L1: sales_stream | M1: Shipping date | N1: distributor_stream | O1: po_number | P1: Partner | Q1: Product Price | R1: PO_price | AB1: 收到订单日期 | AC1: 销售渠道 | AD1: 发货日期 | AE1: 销售途径 | AF1: 订单号 | AG1: 品牌 | AH1: 订单价格
A2: BCLDB_WT | B2: 45797 | C2: Provincial Distribution | D2: PO_50044423 | E2: 1 | H2: level 1 | I2: =56*5.5*5.5 -> 1694 | K2: Shipping date | L2: distributor_stream | M2: po_number | N2: product_name | O2: ProductLot# | P2: Excised(Yes/No) | Q2: Excisedfor | R2: packondate_labelled | AA2: =AF2&AG2 -> PO_0082726_legacy250403-1Aviator Cannabis Co. | AB2: 45747 | AC2: OCS_redistribution | AD2: 45750 | AE2: Provincial Distribution | AF2: PO_0082726_legacy250403-1 | AG2: Aviator Cannabis Co. | AH2: {=SUMIF(S2:S57,AA2:AA23,R2:R57)} -> 0
A3: YLC | B3: 45799 | C3: Provincial Distribution | D3: PO_00023226 | E3: 2 | H3: level 2 | I3: 1375 | K3: 45790 | L3: Provincial Distribution | M3: PO_494609_OFDMB | N3: November Rain Blast Pre-Roll - Blueberry-3 x 0.5g Pre-Roll | Q3: MB | AA3: =AF3&AG3 -> PO_0082726_legacy250403-1Apothecary Botanicals | AB3: 45747 | AC3: OCS_redistribution | AD3: 45750 | AE3: Provincial Distribution | AF3: PO_0082726_legacy250403-1 | AG3: Apothecary Botanicals | AH3: 0
A4: BCDD | B4: 45797 | C4: Retail | D4: PO_1113 | E4: 3 | H4: level 3 | I4: 825 | K4: 45791 | L4: Retail | M4: PO_1111 | N4: November Rain Blast Pre-Roll - Watermelon-3 x 0.5g Pre-Roll | Q4: MB | AA4: =AF4&AG4 -> PO_1071Apothecary Botanicals | AB4: 45747 | AC4: BCDD | AD4: 45748 | AE4: Retail | AF4: PO_1071 | AG4: Apothecary Botanicals | AH4: 0 | BA4: po_shipdate | BB4: Appointment date | BC4: Appointment # | BD4: Tracking number | BE4: Released (Y/N) | BF4: PO_date | BG4: sales_stream | BH4: Shipping date | BI4: distributor_stream | BJ4: po_number | BK4: product_name | BL4: ProductLot# | BM4: Excised(Yes/No) | BN4: Excisedfor | BO4: packondate_labelled | BP4: quantity_unit | BQ4: unitpercase | BR4: cases | BV4: God's Space Needle Bubble Hash | BW4: WX2021050701A | BX4: 44510 | BY4: 30
A5: BCDD | B5: 45797 | C5: Retail | D5: PO_1114 | E5: 3 | H5: level 4 | I5: 825 | K5: 45790 | L5: Provincial Distribution | M5: PO_495906_OFDMB | N5: November Rain Pre-Roll - Rose-3 x 0.5g Pre-Roll | Q5: MB | AA5: =AF5&AG5 -> PO_1070Apothecary Botanicals | AB5: 45747 | AC5: BCDD | AD5: 45748 | AE5: Retail | AF5: PO_1070 | AG5: Apothecary Botanicals | AH5: 0 | BA5: 45792 | BC5: NEED BOOKING | BF5: 45749 | BG5: AGLC | BI5: Provincial Distribution | BJ5: PO_74167 | BK5: THC oil 30 ml | BL5: EX24101802V30 | BM5: THC oil 27.6g | BN5: extract_ingested_cased_MB | BO5: 45588 | BP5: 108 | BQ5: 6 | BR5: 18 | BV5: Tundra Bubble Bubble Hash | BW5: CW22011701 | BX5: 44879 | BY5: 30
A6: BCDD_ROGWORLD | B6: 45797 | C6: Retail | D6: PO_1114 | E6: 4 | H6: level 5 | I6: 750 | K6: 45791 | L6: Retail | M6: PO_1112 | N6: November Rain Infused Pre-Roll - Rose-3 x 0.5g Pre-Roll | O6: PR2303IN02F5P3 | P6: YES | Q6: BC | R6: 45478 | AA6: =AF6&AG6 -> PO_475927_OFDMBApothecary Botanicals | AB6: 45748 | AC6: MBLL_redistribution | AD6: 45748 | AE6: Provincial Distribution | AF6: PO_475927_OFDMB | AG6: Apothecary Botanicals | AH6: 0 | BA6: 45792 | BC6: NEED BOOKING | BF6: 45749 | BG6: AGLC | BI6: Provincial Distribution | BJ6: PO_74167 | BK6: November Rain Pre-Roll - Trident Pre-Roll -3 x 0.5g | BL6: PR241104F5P3 | BM6: November Rain Trident preroll 3 x 0.5g | BN6: preroll_cased_ON | BO6: 45588 | BP6: 300 | BQ6: 12 | BR6: 25 | BV6: Romulan Grape God Bubble Hash | BW6: CW2103051 | BX6: 44806 | BY6: 30
A7: BCDD | B7: 45797 | C7: Retail | D7: PO_1115 | E7: 5 | H7: level 6 | I7: 625 | K7: 45792 | L7: Retail | M7: PO_DD_Weeds2025051401 | N7: November Rain- White Widow Live Resin Extract 1G LTO! | O7: LR23032101 | P7: YES | Q7: BC | R7: 45793 | AA7: =AF7&AG7 -> PO_1072Apothecary Botanicals | AB7: 45748 | AC7: BCDD | AD7: 45750 | AE7: Retail | AF7: PO_1072 | AG7: Apothecary Botanicals | AH7: 0 | BA7: 45792 | BC7: NEED BOOKING | BF7: 45749 | BG7: AGLC | BI7: Provincial Distribution | BJ7: PO_74167 | BK7: November Rain Pre-Roll - Monkey King Pre-Roll- 2 x 0.5g | BL7: PR2401F5P2 | BM7: Monkey King preroll 2 x 0.5g | BN7: preroll_labelled | BO7: 45670 | BP7: 180 | BQ7: 12 | BR7: 15 | BV7: Venom OG Live Rosin | BW7: 25-FP001 | BX7: 45739 | BY7: 30
A8: BCDD | B8: 45797 | C8: Retail | D8: PO_1116 | E8: 6 | H8: level 7 | I8: 574.75 | K8: 45791 | L8: Intra Industry | M8: PO_02279 | N8: Gelato Prerolls 3x0.5g | O8: PR21071201G5 | P8: YES | Q8: BC | R8: 45779 | AA8: =AF8&AG8 -> PO_476527Apothecary Botanicals | AB8: 45749 | AC8: MBLL_redistribution | AD8: 45749 | AE8: Provincial Distribution | AF8: PO_476527 | AG8: Apothecary Botanicals | AH8: 0 | BA8: 45792 | BC8: NEED BOOKING | BF8: 45749 | BG8: AGLC | BI8: Provincial Distribution | BJ8: PO_74167 | BK8: November Rain Blast Pre-Roll - Blueberry-3 x 0.5g Pre-Roll | BN8: AB | BP8: 210 | BQ8: 6 | BR8: 35 | BV8: Northern Apple Jaxx Live Rosin | BW8: RP24001 | BX8: 45605 | BY8: 30
A9: BCDD | B9: 45797 | C9: Retail | D9: PO_1117 | E9: 6 | H9: level 8 | K9: 45793 | L9: Provincial Distribution | M9: PO_498186_OFDMB | N9: ROGWORLD-Lemonade Octane Live Resin Biodegradable Hemp Vape Pen 1g | O9: ROGEX001G1 | P9: YES | Q9: BC | R9: 45740 | AA9: =AF9&AG9 -> PO_1073Apothecary Botanicals | AB9: 45748 | AC9: BCDD | AD9: 45750 | AE9: Retail | AF9: PO_1073 | AG9: Apothecary Botanicals | AH9: 0 | BA9: 45792 | BC9: NEED BOOKING | BF9: 45749 | BG9: AGLC | BI9: Provincial Distribution | BJ9: PO_74167 | BK9: Midnight Kruntz 7g dried flower | BN9: AB | BP9: 300 | BQ9: 6 | BR9: 50 | BV9: Live Duo | BW9: FP23004 | BX9: 45689 | BY9: 18
A10: MBLL_redistribution | B10: 45797 | C10: Provincial Distribution | D10: PO_499949_OFDMB | E10: 7 | N10: Midnight Kruntz 10x0.5g preroll | O10: PR2501F5P10 | P10: YES | Q10: BC | R10: 45707 | AA10: =AF10&AG10 -> PO_74167Apothecary Botanicals | AB10: 45749 | AC10: AGLC | AE10: Provincial Distribution | AF10: PO_74167 | AG10: Apothecary Botanicals | AH10: 0 | BA10: 45803 | BC10: NEED BOOKING | BF10: 45757 | BG10: AGLC | BI10: Provincial Distribution | BJ10: PO_74327 | BK10: November Rain Blast Pre-Roll - Blueberry-3 x 0.5g Pre-Roll | BL10: PR251105F5P3 | BM10: YES | BN10: AB | BO10: 45763 | BP10: 600 | BQ10: 6 | BR10: 100 | BV10: Synergy Oil | BW10: EX24092701V30 | BX10: 45640
A11: BCDD | B11: 45799 | C11: Retail | D11: PO_1118 | E11: 8 | N11: November Rain Pre-roll - Animal Mintz 2x1g | O11: PR2507F1P2 | P11: YES | Q11: BC | R11: 45772 | AA11: =AF11&AG11 -> PO_Burb2025040201BURB | AB11: 45750 | AC11: DD_BURB | AD11: 45751 | AE11: Retail | AF11: PO_Burb2025040201 | AG11: BURB | AH11: 0 | BF11: 45762 | BG11: BCDD | BH11: 45764 | BI11: Retail | BJ11: PO_1095 | BK11: Pot Shot- Tropical Fruit | BL11: EX25012101V50 | BM11: YES | BN11: BC | BO11: 45700 | BP11: 24 | BQ11: 12 | BR11: 2
A12: BCDD | B12: 45799 | C12: Retail | D12: PO_1119 | E12: 9 | N12: Pot Shot- Tropical Fruit | Q12: MB | AA12: =AF12&AG12 -> PO_1075Apothecary Botanicals | AB12: 45750 | AC12: BCDD | AD12: 45750 | AE12: Retail | AF12: PO_1075 | AG12: Apothecary Botanicals | AH12: 0 | BF12: 45762 | BG12: BCDD | BH12: 45764 | BI12: Retail | BJ12: PO_1095 | BK12: Gastro-pop Diamond Infused 3x0.5g pre-rolls | BL12: PR2501INF5P3 | BM12: YES | BN12: BC | BO12: 45756 | BP12: 12 | BQ12: 12 | BR12: 1
A13: MBLL_redistribution | B13: 45798 | C13: Provincial Distribution | D13: PO_500367_OFDMB | E13: 10 | N13: November Rain Pre-roll - Animal Mintz 2x1g | O13: PR2507F1P2 | P13: YES | Q13: BC | R13: 45772 | AA13: =AF13&AG13 -> PO_1076Apothecary Botanicals | AB13: 45750 | AC13: BCDD | AD13: 45751 | AE13: Retail | AF13: PO_1076 | AG13: Apothecary Botanicals | AH13: 0 | BF13: 45762 | BG13: BCDD | BH13: 45764 | BI13: Retail | BJ13: PO_1095 | BK13: Blaster Multi Pack Prerolls 12x0.5g | BL13: PR251108F5P12 | BM13: YES | BN13: BC | BO13: 45755 | BP13: 12 | BQ13: 12 | BR13: 1
A14: MBLL_redistribution | B14: 45799 | C14: Provincial Distribution | D14: PO_500120 | E14: 11 | N14: Blaster Multi Pack Prerolls 12x0.5g | O14: PR251108F5P12 | P14: YES | Q14: BC | R14: 45777 | AA14: =AF14&AG14 | AH14: 594522 | BF14: 45762 | BG14: BCDD | BH14: 45764 | BI14: Retail | BJ14: PO_1095 | BK14: Gelato Prerolls 3x0.5g | BL14: PR2301F5P3 | BM14: YES | BN14: BC | BO14: 45742 | BP14: 12 | BQ14: 12 | BR14: 1
A15: BCDD | B15: 45800 | C15: Retail | D15: PO_1120 | N15: November Rain- White Widow Live Resin Extract 1G LTO! | O15: LR23032101 | P15: YES | Q15: BC | R15: 45793 | AA15: =AF15&AG15 | AH15: 594522 | BF15: 45762 | BG15: BCDD_ROGWORLD | BH15: 45764 | BI15: Retail | BJ15: PO_1095 | BK15: ROGWORLD-Lemonade Octane Live Resin Biodegradable Hemp Vape Pen 1g | BL15: ROGEX001G1 | BM15: YES | BN15: BC | BO15: 45740 | BP15: 12 | BQ15: 12 | BR15: 1
N16: November Rain Blast Pre-Roll - Blueberry-3 x 0.5g Pre-Roll | O16: PR241105F5P3 | P16: YES | Q16: BC | R16: 45581 | AA16: =AF16&AG16 | AH16: 594522 | BA16: 45779 | BF16: 45758 | BG16: BCLDB | BI16: Provincial Distribution | BJ16: PO_50043536 | BK16: Maximum Strength CBD Roll-on Topical Cream | BN16: BC | BP16: 600 | BQ16: 12 | BR16: 50
N17: Midnight Kruntz 10x0.5g preroll | O17: PR2516F5P10 | P17: YES | Q17: BC | R17: 45772 | AA17: =AF17&AG17 | AH17: 594522 | BA17: 45792 | BF17: 45757 | BG17: BCLDB_ROGWORLD | BI17: Provincial Distribution | BJ17: PO_50043425 | BK17: ROGWORLD-RUNTZ MUFFIN CRUMBLE-1G | BN17: BC | BP17: 1800 | BQ17: 12 | BR17: 150
N18: WEEDS-PINEAPPLE SOUR-28G | O18: 2025030701G28 | P18: YES | Q18: BC | R18: 45786 | AA18: =AF18&AG18 | AH18: 594522 | BA18: 45768 | BF18: 45754 | BG18: BCLDB_WT | BI18: Provincial Distribution | BJ18: PO_50043351 | BK18: Super Sativa Oil 27.6 g | BN18: BC | BP18: 420 | BQ18: 6 | BR18: 70
N19: Rilaxe The One Night Stand Blunt 1x1g | O19: PR2515F1P1 | P19: YES | Q19: ON | R19: 45772 | AA19: =AF19&AG19 | AH19: 594522 | BF19: 45761 | BG19: Cannmart | BI19: Intra Industry | BJ19: PO_02276 | BK19: Rilaxe The One Night Stand Blunt 1x1g | BN19: AB | BQ19: 12 | BR19: 0
N20: Pot Shot- Tropical Fruit | Q20: MB | AA20: =AF20&AG20 | AH20: 594522 | BF20: 45735 | BG20: DD_WT | BI20: Retail | BJ20: PO_sumtDDwt250317 | BK20: Grapefruit Cake MAC Live Rosin | BN20: BC | BP20: 12 | BQ20: 6 | BR20: 2
S21: =O21&P21 | AA21: =AF21&AG21 | AH21: 594522 | BA21: 45778 | BC21: NEED BOOKING | BF21: 45757 | BG21: OCS | BI21: Provincial Distribution | BJ21: PO_0082982 | BK21: Pot Shot- Coconut Lime | BN21: ON | BP21: 84 | BQ21: 12 | BR21: 7
S22: =O22&P22 | AA22: =AF22&AG22 | AH22: 594522 | AN22: PO_date | AO22: sales_stream | AP22: Shipping date | AQ22: po_number | BA22: 45778 | BC22: NEED BOOKING | BF22: 45757 | BG22: OCS | BI22: Provincial Distribution | BJ22: PO_0082982 | BK22: Apothecary Botanicals Topical CBD Mini Roll-on 45 g | BN22: ON | BP22: 12 | BQ22: 12 | BR22: 1
S23: =O23&P23 | AA23: =AF23&AG23 | AH23: 594522 | AO23: BCLDB_WT | AP23: 45744 | AQ23: PO_50041983 | BA23: 45778 | BC23: NEED BOOKING | BF23: 45757 | BG23: OCS | BI23: Provincial Distribution | BJ23: PO_0083270 | BK23: Maximum Strength CBD Roll-on Topical Cream | BN23: ON | BP23: 108 | BQ23: 12 | BR23: 9
S24: =O24&P24 | AO24: Medicibis | AP24: 45744 | AQ24: PO_00001786 | BA24: 45764 | BC24: NEED BOOKING | BF24: 45761 | BG24: OCS | BH24: 45764 | BI24: Provincial Distribution | BJ24: PO_0083524 | BK24: Pot Shot- Tropical Fruit | BL24: EX25012101V50 | BM24: YES | BN24: ON | BO24: 45700 | BP24: 60 | BQ24: 12 | BR24: 5
S25: =O25&P25 | AR25: OCS | AS25: 45743 | AT25: PO_0080542_legacy250327 | BA25: 45764 | BC25: NEED BOOKING | BF25: 45761 | BG25: OCS | BH25: 45764 | BI25: Provincial Distribution | BJ25: PO_0083524 | BK25: November Rain Blast Pre-Roll - Blueberry-3 x 0.5g Pre-Roll | BL25: PR241105F5P3 | BM25: YES | BN25: ON | BO25: 45756 | BP25: 24 | BQ25: 12 | BR25: 2
S26: =O26&P26 | AR26: BCLDB_WT | AS26: 45744 | AT26: PO_50042503 | BA26: 45764 | BC26: NEED BOOKING | BF26: 45761 | BG26: OCS | BH26: 45764 | BI26: Provincial Distribution | BJ26: PO_0083524 | BK26: November Rain Vape Canadian Thunder 0.5g Sativa | BL26: EX24111301G05 | BM26: YES | BN26: ON | BO26: 45749 | BP26: 12 | BQ26: 12 | BR26: 1
S27: =O27&P27 | AR27: BCLDB_WT | AS27: 45744 | AT27: PO_50042517 | BA27: 45776 | BF27: 45754 | BG27: SLGA_redistribution | BI27: Intra Industry | BJ27: PO_04-040725 | BK27: Midnight Kruntz 7g dried flower | BN27: SK | BP27: 360 | BQ27: 12 | BR27: 30
S28: =O28&P28 | U28: {=_xlfn.UNIQUE(K1:P57)} -> PO_date | V28: sales_stream | W28: Shipping date | X28: distributor_stream | Y28: po_number | Z28: Partner | AQ28: 45743 | AR28: Sample | AS28: 45743 | AT28: steve250327 | BA28: 45776 | BF28: 45754 | BG28: SLGA_redistribution | BI28: Intra Industry | BJ28: PO_04-040725 | BK28: Midnight Kruntz 10x0.5g preroll | BN28: SK | BP28: 180 | BQ28: 12 | BR28: 15
S29: =O29&P29 | U29: Shipping date | V29: distributor_stream | W29: po_number | X29: product_name | Y29: ProductLot# | Z29: Excised(Yes/No) | AQ29: 45741 | AR29: MBLL_redistribution | AS29: 45743 | AT29: PO_472627_OFDMB | BF29: 45763 | BG29: BCDD | BI29: Retail | BJ29: PO_1096 | BK29: November Rain Vape Tropical Meteor Shower 0.5g Sativa | BL29: EX24101703G05 | BM29: November Rain Vape Tropical Meteor Shower 0.5g Sativa | BN29: extract_inhaled_labelled | BO29: 45603 | BP29: 24 | BQ29: 12 | BR29: 2
S30: =O30&P30 | U30: 45790 | V30: Provincial Distribution | W30: PO_494609_OFDMB | X30: November Rain Blast Pre-Roll - Blueberry-3 x 0.5g Pre-Roll | Y30: 0 | Z30: 0 | AQ30: 45743 | AR30: NTLCC | AS30: 45744 | AT30: PO_10013414 | BF30: 45763 | BG30: BCDD | BI30: Retail | BJ30: PO_1096 | BK30: November Rain Vape Concord Grape 1g | BL30: EX25020601G1 | BM30: November Rain Concord Grape vape 1g | BN30: extract_inhaled_labelled | BO30: 45707 | BP30: 24 | BQ30: 12 | BR30: 2
S31: =O31&P31 | U31: 45791 | V31: Retail | W31: PO_1111 | X31: November Rain Blast Pre-Roll - Watermelon-3 x 0.5g Pre-Roll | Y31: 0 | Z31: 0 | AQ31: 45743 | AR31: BCDD | AS31: 45744 | AT31: PO_1069 | BF31: 45763 | BG31: BCDD | BI31: Retail | BJ31: PO_1096 | BK31: November Rain Blast Pre-Roll - Blueberry-3 x 0.5g Pre-Roll | BL31: PR241105F5P3 | BM31: November Rain Blueberry preroll 3 x 0.5g | BN31: preroll_labelled | BO31: 45581 | BP31: 1 | BQ31: 12 | BR31: 0.083333333
S32: =O32&P32 | U32: 45790 | V32: Provincial Distribution | W32: PO_495906_OFDMB | X32: November Rain Pre-Roll - Rose-3 x 0.5g Pre-Roll | Y32: 0 | Z32: 0 | AR32: BCDD | AS32: 45748 | AT32: PO_1071 | BF32: 45763 | BG32: BCDD | BI32: Retail | BJ32: PO_1096 | BK32: November Rain Blast Pre-Roll - Blueberry-3 x 0.5g Pre-Roll | BP32: 35 | BQ32: 12 | BR32: 2.9166667
S33: =O33&P33 | U33: 45791 | V33: Retail | W33: PO_1112 | X33: November Rain Infused Pre-Roll - Rose-3 x 0.5g Pre-Roll | Y33: PR2303IN02F5P3 | Z33: YES | AR33: BCDD | AS33: 45748 | AT33: PO_1070 | BF33: 45763 | BG33: BCDD | BI33: Retail | BJ33: PO_1096 | BK33: November Rain Blast Pre-Roll - Lemon ice tea-3 x 0.5g Pre-Roll | BL33: PR241101F5P3 | BM33: November Rain Lemon Ice Tea preroll 3 x 0.5g | BN33: preroll_labelled | BO33: 45707 | BP33: 17 | BQ33: 12 | BR33: 1.4166667
S34: =O34&P34 | U34: 45792 | V34: Retail | W34: PO_DD_Weeds2025051401 | X34: November Rain- White Widow Live Resin Extract 1G LTO! | Y34: LR23032101 | Z34: YES | AR34: MBLL_redistribution | AS34: 45749 | AT34: PO_476527 | BF34: 45763 | BG34: BCDD | BI34: Retail | BJ34: PO_1096 | BK34: November Rain Blast Pre-Roll - Lemon ice tea-3 x 0.5g Pre-Roll | BN34: BC | BP34: 19 | BQ34: 12 | BR34: 1.5833333
S35: =O35&P35 | U35: 45791 | V35: Intra Industry | W35: PO_02279 | X35: Gelato Prerolls 3x0.5g | Y35: PR21071201G5 | Z35: YES | BF35: 45764 | BG35: BCDD | BH35: 45764 | BI35: Retail | BJ35: PO_1097 | BK35: November Rain Pre-roll - Animal Mintz 2x1g | BN35: BC | BP35: 12 | BQ35: 12 | BR35: 1
S36: =O36&P36 | U36: 45793 | V36: Provincial Distribution | W36: PO_498186_OFDMB | X36: ROGWORLD-Lemonade Octane Live Resin Biodegradable Hemp Vape Pen 1g | Y36: ROGEX001G1 | Z36: YES | BF36: 45764 | BG36: BCDD_ROGWORLD | BH36: 45764 | BI36: Retail | BJ36: PO_1097 | BK36: ROGWORLD-Lemonade Octane Live Resin Biodegradable Hemp Vape Pen 1g | BN36: BC | BP36: 12 | BQ36: 12 | BR36: 1
S37: =O37&P37 | U37: 0 | V37: 0 | W37: 0 | X37: Midnight Kruntz 10x0.5g preroll | Y37: PR2501F5P10 | Z37: YES | BF37: 45763 | BG37: BCDD | BH37: 45764 | BI37: Retail | BJ37: PO_10013 | BK37: Pot Shot- Tropical Fruit | BN37: BC | BP37: 12 | BQ37: 12 | BR37: 1
S38: =O38&P38 | U38: 0 | V38: 0 | W38: 0 | X38: November Rain Pre-roll - Animal Mintz 2x1g | Y38: PR2507F1P2 | Z38: YES | BF38: 45763 | BG38: BCDD | BH38: 45764 | BI38: Retail | BJ38: PO_10013 | BK38: Pot Shot- Citrus | BN38: BC | BP38: 12 | BQ38: 12 | BR38: 1
S39: =O39&P39 | U39: 0 | V39: 0 | W39: 0 | X39: Pot Shot- Tropical Fruit | Y39: 0 | Z39: 0
S40: =O40&P40 | U40: 0 | V40: 0 | W40: 0 | X40: Blaster Multi Pack Prerolls 12x0.5g | Y40: PR251108F5P12 | Z40: YES
...

Sheet Sheet2
A1: po_number | B1: product_name | C1: ProductLot# | D1: Excised(Yes/No) | E1: Excisedfor | F1: packondate_labelled | G1: quantity_unit | H1: unitpercase | I1: cases | J1: cannabis_netweight_gram
A2: PO_DD_Burb2025020401 | B2: Blue Gumdrop 5 x 0.5g Pre Roll | C2: PR2503F5P5 | D2: YES | E2: BC | F2: 45685 | G2: 324 | H2: 12 | I2: 27 | J2: 810
A3: PO_DD_Burb2025041701 | B3: Blue Gumdrop 5 x 0.5g Pre Roll | C3: PR2514F5P5 | D3: YES | E3: BC | F3: 45765 | G3: 480 | H3: 12 | I3: 40 | J3: 1200
A4: PO_Burb2025060501 | B4: Blue Gumdrop 5 x 0.5g Pre Roll | C4: PR2514F5P5 | D4: YES | E4: BC | F4: 45814 | G4: 408 | H4: 12 | I4: 34 | J4: 1020
A5: PO_50040988 | B5: Book Club-Blue Gumdrop 14g | C5: 2025010201G14 | D5: YES | E5: BC | F5: 45693 | G5: 750 | H5: 6 | I5: 125 | J5: 10500
A6: PO_50041554 | B6: Book Club-Blue Gumdrop 14g | C6: 2025010201G14 | D6: YES | E6: BC | F6: 45709 | G6: 600 | H6: 6 | I6: 100 | J6: 8400
A7: PO_DD_Burb_2025012801 | B7: Book Club-Blue Gumdrop 28g | C7: 2024120501G28 | D7: YES | E7: BC | F7: 45682 | G7: 144 | H7: 12 | I7: 12 | J7: 4032
A8: PO_Burb2025040201 | B8: Book Club-Blue Gumdrop 28g | C8: 2024120501G28 | D8: YES | E8: BC | F8: 45744 | G8: 108 | H8: 12 | I8: 9 | J8: 3024
A9: PO_Burb2025060501 | B9: Book Club-Blue Gumdrop 28g | C9: 2025042201G28 | D9: YES | E9: BC | F9: 45805 | G9: 180 | H9: 12 | I9: 15 | J9: 5040 | K9: =SUM(J2:J9) -> 34026
A10: DD_burb_2025022001 | B10: Book Club-Kruntz 28g | C10: 2024121801G28 | D10: yes | E10: BC | F10: 45707 | G10: 300 | H10: 12 | I10: 25 | J10: 8400
A11: DD_Burb2025031401 | B11: BOOK CLUB-LICORICE GUMBALL Preroll 5x0.5g | C11: PR2505F5P5 | D11: YES | E11: BC | F11: 45730 | G11: 492 | H11: 12 | I11: 41 | J11: 1230
A12: PO_Burb2025060501 | B12: BOOK CLUB-LICORICE GUMBALL Preroll 5x0.5g | C12: PR2505F5P5 | D12: YES | E12: BC | F12: 45814 | G12: 360 | H12: 12 | I12: 30 | J12: 900
A13: PO_DD2024102301 | B13: BOOK CLUB-LICORICE GUMBALL-14G | C13: 2024092002 | D13: YES | E13: BC | F13: 45581 | G13: 1149 | H13: 12 | I13: 95.75 | J13: 16086
A14: PO_DD2024102301 | B14: BOOK CLUB-LICORICE GUMBALL-14G | C14: 2024092003 | D14: YES | E14: BC | F14: 45581 | G14: 411 | H14: 12 | I14: 34.25 | J14: 5754 | K14: =SUM(J11:J14) -> 23970
A15: PO_DD_Burb_2025012801 | B15: Book Club-Pressure Pie 28g | C15: 2024110601G28 | D15: YES | E15: BC | F15: 45682 | G15: 144 | H15: 12 | I15: 12 | J15: 4032
A16: PO_Burb2025040201 | B16: Book Club-Pressure Pie 28g | C16: 2024110601G28 | D16: YES | E16: BC | F16: 45744 | G16: 156 | H16: 12 | I16: 13 | J16: 4368 | K16: =SUM(J15:J16)+SUM(J20:J22) -> 10260
A17: DD_Burb2025031401 | B17: BOOK CLUB-Unicorn Poop Preroll 5x0.5g | C17: PR2506F5P5 | D17: YES | E17: BC | F17: 45723 | G17: 492 | H17: 12 | I17: 41 | J17: 1230
A18: PO_Burb2025060501 | B18: BOOK CLUB-Unicorn Poop Preroll 5x0.5g | C18: PR2506F5P5 | D18: YES | E18: BC | F18: 45814 | G18: 516 | H18: 12 | I18: 43 | J18: 1290
A19: PO_DD2024102301 | B19: BOOK CLUB-UNICORN POOP-14G | C19: 2024092001 | D19: YES | E19: BC | F19: 45581 | G19: 888 | H19: 12 | I19: 74 | J19: 12432 | K19: =SUM(J17:J19) -> 14952
A20: PO_DD_Burb2025020401 | B20: Pressure Pie 5 x 0.5g Pre Roll | C20: PR2502F5P5 | D20: YES | E20: BC | F20: 45685 | G20: 336 | H20: 12 | I20: 28 | J20: 840
A21: PO_DD_Burb2025041701 | B21: Pressure Pie 5 x 0.5g Pre Roll | C21: PR2502F5P5 | D21: YES | E21: BC | F21: 45765 | G21: 396 | H21: 12 | I21: 33 | J21: 990
A22: PO_Burb2025060501 | B22: Pressure Pie 5 x 0.5g Pre Roll | C22: PR2502F5P5 | D22: YES | E22: BC | F22: 45814 | G22: 12 | H22: 12 | I22: 1 | J22: 30
L24: shipment (S) | M24: name | N24: receiving net (R) | O24: expected inventory (S-R) | P24: actual inventory (A) | Q24: A-E | R24: allowed difference (gram)=5% *R | S24: (A-E)/R | U24: OUTBOUND GROSS (O) | V24: # BAGV(B) | W24: (O-R)/R/B | X24: O-S | Y24: (O-S)/B/R
L25: =K9 -> 34026 | M25: blue gumdrop | N25: =8300+21800+5240 -> 35340 | O25: =N25-L25 -> 1314 | P25: =L55 -> 182 | Q25: =P25-O25 -> -1132 | R25: =0.05*N25 -> 1767 | S25: =Q25/N25 -> -0.032031692 | U25: 41073.5 | V25: 20 | W25: =(U25-N25)/N25/V25 -> 0.0081119128 | X25: =U25-L25 -> 7047.5 | Y25: =X25/V25/N25 -> 0.009970996
M26: kruntz
L30: =K14 -> 23970 | M30: licorice gumball | N30: =16000+5900 -> 21900 | O30: =N30-L30 -> -2070 | P30: =L53 -> 7447 | Q30: =P30-O30 -> 9517 | R30: =0.05*N30 -> 1095 | S30: =Q30/N30 -> 0.43456621 | T30: *** | U30: 22416 | V30: 10 | W30: =(U30-N30)/N30/V30 -> 0.0023561644 | X30: =U30-L30 -> -1554 | Y30: =X30/V30/N30 -> -0.0070958904
L32: =K16 -> 10260 | M32: pressure pie | N32: 15863 | O32: =N32-L32 -> 5603 | P32: =L50 -> 5056 | Q32: =P32-O32 -> -547 | R32: =0.05*N32 -> 793.15 | S32: =Q32/N32 -> -0.034482759 | U32: 11213 | V32: 7 | W32: =(U32-N32)/N32/V32 -> -0.041876424 | X32: =U32-L32 -> 953 | Y32: =X32/V32/N32 -> 0.0085824155
L35: =K19 -> 14952 | M35: unicorn poop | N35: 12500 | O35: =N35-L35 -> -2452 | P35: =L54 -> -3398 | Q35: =P35-O35 -> -946 | R35: =0.05*N35 -> 625 | S35: =Q35/N35 -> -0.07568 | T35: * | U35: 13002 | V35: 4 | W35: =(U35-N35)/N35/V35 -> 0.01004 | X35: =U35-L35 -> -1950 | Y35: =X35/V35/N35 -> -0.039
L38: =SUM(L25:L35) -> 83208 | M38: TOTAL | N38: =SUM(N25:N35) -> 85603 | O38: =SUM(O25:O35) -> 2395 | P38: =SUM(P25:P35) -> 9287 | Q38: =P38-O38 -> 6892 | R38: =0.05*N38 -> 4280.15 | S38: =Q38/N38 -> 0.080511197 | T38: * | U38: =SUM(U25:U37) -> 87704.5 | V38: =SUM(V25:V37) -> 41 | W38: =(U38-N38)/N38/V38 -> 0.0005987652 | X38: =U38-L38 -> 4496.5 | Y38: =X38/V38/N38 -> 0.0012811552
M39: R-S | N39: =N38-L38 -> 2395
M40: (R-S)/R | N40: =N39/N38 -> 0.027977991
L47: actual inventory | M47: product_description | N47: lot_number | O47: pack_on_date | P47: quantity_unit | Q47: unit_name | R47: gross_weight | S47: net_weight | T47: check_time
M48: Pressure Pie dried flower | N48: 2024110601 | O48: NA | P48: 1 | Q48: unit | R48: 1514 | S48: 1419 | T48: 45748.705
M49: Pressure Pie dried flower | N49: 2024110601 | O49: NA | P49: 1 | Q49: unit | R49: 3090 | S49: 3000 | T49: 45609.687
L50: =SUM(S48:S50) -> 5056 | M50: Pressure Pie dried flower | N50: 2024110601 | O50: NA | P50: 1 | Q50: unit | R50: 724 | S50: 637 | T50: 45748.705
M51: Licorice Gumball milled flower | N51: PR2505 | O51: NA | P51: 1 | Q51: pail | R51: 2358 | S51: 618 | T51: 45811.644
M52: Licorice Gumball milled flower | N52: PR2505 | O52: NA | P52: 1 | Q52: pail | R52: 4426 | S52: 2676 | T52: 45698.635
L53: =SUM(S51:S53) -> 7447 | M53: Licorice Gumball milled flower | N53: PR2505 | O53: NA | P53: 1 | Q53: pail | R53: 5867 | S53: 4153 | T53: 45698.635
L54: -3398 | M54: Unicorn Poop milled flower | N54: PR2506 | O54: NA | P54: 0 | Q54: pail | R54: -3398 | S54: NULL | T54: 45803.417
L55: 182 | M55: Blue Gum Dried Flower Grade A | N55: 2025042201 | O55: NA | P55: 1 | Q55: bag | R55: 240 | S55: 182 | T55: 45821.625

Sheet Sheet3
A1: PO | B1: weight | C1: length | D1: width | E1: height | F1: tracking | G1: cost
B2: 3 | C2: 6 | D2: 6 | E2: 6 | F2: 335446020356 | G2: 43.69
A3: PO_503021 | B3: 3 | C3: 6 | D3: 6 | E3: 6 | F3: 335459704466 | G3: 58
A4: PO_502181_APOTHECARY | B4: 2 | C4: 8 | D4: 6 | E4: 4 | F4: 335460761315 | G4: 40.3
A5: PO_503918 | B5: 3 | C5: 6 | D5: 6 | E5: 6 | F5: 335468042262 | G5: 42
A6: PO_00001976 | B6: 61 | C6: 22 | D6: 22 | E6: 22 | F6: 335470535790 | G6: 204.44
A7: PO_00001976 | B7: 15.8 | C7: 22 | D7: 10 | E7: 6 | F7: 335470535790 | G7: 204.44
A8: PO_00001976 | B8: 15.8 | C8: 22 | D8: 10 | E8: 6 | F8: 335470535790 | G8: 204.44
A9: PO_504787 | B9: 3 | C9: 6 | D9: 6 | E9: 6 | F9: 335470838434 | G9: 43.92
A10: PO_505918 | B10: 3 | C10: 6 | D10: 6 | E10: 6 | F10: 335478543960 | G10: 40.47
A11: PO_507848 | F11: 335489377077 | G11: 38.42
A12: PO_507266 | B12: 3 | C12: 6 | D12: 6 | E12: 6 | F12: 335489416180 | G12: 38.88
A13: PO_507860 | B13: 3 | C13: 6 | D13: 6 | E13: 6 | F13: 335489430561 | G13: 38.88
A14: PO_00023299 | B14: 16 | C14: 24 | D14: 12 | E14: 16 | F14: 335493026348 | G14: 136.26
A15: PO_508181 | B15: 13 | C15: 13 | D15: 13 | E15: 9 | F15: 335493961981 | G15: 50.14
A16: OFDMB250609 | B16: 45 | C16: 24 | D16: 19 | E16: 12 | F16: 335494035876 | G16: 87.85
A17: PO_1131 | B17: 6 | C17: 14 | D17: 14 | E17: 6 | F17: 335499234102 | G17: 35.89
A18: PO_05-05225 | B18: 12 | C18: 22 | D18: 17 | E18: 8 | F18: 335506475243 | G18: 233.93/3
A19: PO_05-05225 | B19: 18 | C19: 22 | D19: 17 | E19: 12 | F19: 335506475243 | G19: 233.93/3
A20: PO_05-05225 | B20: 90 | C20: 22 | D20: 22 | E20: 22 | F20: 335506475243 | G20: 233.93/3
A21: PO_512279 | B21: 1 | C21: 4 | D21: 3 | E21: 2 | F21: 335511282345 | G21: 40
A22: PO_1133 | B22: 3 | C22: 12 | D22: 10 | E22: 6 | F22: 335514537778
A23: PO_1138 | B23: 4 | C23: 5 | D23: 13 | E23: 10 | F23: 335520160920 | G23: 20.68
A24: PO_1137 | B24: 3 | C24: 6 | D24: 12 | E24: 12 | F24: 335520177619 | G24: 19.07
A25: PO_515049 | B25: 3 | C25: 8 | D25: 11 | E25: 4 | F25: 335523600518 | G25: 30.4
A26: highway250624 | B26: 1 | C26: 2 | D26: 4 | E26: 7 | F26: 335529225724 | G26: 34
A27: PO_1143 | B27: 3 | C27: 12 | D27: 12 | E27: 12 | F27: 335535301782 | G27: 30
A28: PO_06-062625 | B28: 18 | C28: 24 | D28: 12 | E28: 18 | F28: 335539111070 | G28: 79.14
A29: PO_520696 | B29: 2 | C29: 6 | D29: 6 | E29: 6 | F29: 335550586440 | G29: 41.43
A30: PO_519039 | B30: 2 | C30: 6 | D30: 6 | E30: 6 | F30: 335550589048 | G30: 38.42
A31: PO_524578 | B31: 1 | C31: 8 | D31: 6 | E31: 5 | F31: 335563652130 | G31: 38
A32: legacy250710 | B32: 16 | C32: 12 | D32: 12 | E32: 12 | F32: 335566393450 | G32: 95.26
A33: PO_00002111 | B33: 50 | C33: 20 | D33: 16 | E33: 8 | G33: 765.14
A34: PO_00002111 | B34: 100.8 | C34: 22 | D34: 18 | E34: 10 | G34: 765.14
A35: PO_00002111 | B35: 12 | C35: 22 | D35: 10 | E35: 6 | G35: 765.14
A36: PO_00002111 | B36: 11 | C36: 22 | D36: 10 | E36: 6 | G36: 765.14
A37: PO_00002111 | B37: 6 | C37: 22 | D37: 10 | E37: 6 | G37: 765.14
A38: PO_00002111 | B38: 11 | C38: 22 | D38: 10 | E38: 6 | G38: 765.14
A39: PO_00002111 | B39: 8.7 | C39: 12 | D39: 12 | E39: 6 | G39: 765.14
A40: PO_00002111 | B40: 11 | C40: 22 | D40: 10 | E40: 6 | G40: 765.14
...

Sheet Sheet4
A1: calculation_method | B1: net | F1: calculation_method | G1: (Multiple Items) | I1: calculation_method | J1: gross | N1: calculation_method | O1: gross
A3: Row Labels | B3: Sum of number_of_unit | F3: Row Labels | G3: Sum of quantity_change_unit | I3: Row Labels | J3: Sum of gross_weight | N3: Row Labels | O3: Sum of quantity_change_gross_weight
A4: #1 | B4: 0 | C4: =VLOOKUP(A4,F:G,2,0) -> #N/A | D4: =IF(ISERROR(C4),B4,B4+C4) -> 0 | I4: Abby Leaf Inc Licorish Gumball dried flower | J4: 6096 | K4: =VLOOKUP(I4,N:O,2,0) -> -5396 | L4: =IF(ISERROR(K4),J4,J4+K4) -> 700 | N4: Abby Leaf Inc Licorish Gumball dried flower | O4: -5396
A5: 20:1 Mango CBD:THC extract 29.5g | B5: 20 | C5: =VLOOKUP(A5,F:G,2,0) -> #N/A | D5: =IF(ISERROR(C5),B5,B5+C5) -> 20 | F5: Animal Mint pre-roll 2 x 1g | G5: -2646 | I5: Abby Leaf Inc Licorish Gumball dried flower Grade A | J5: 10898 | K5: =VLOOKUP(I5,N:O,2,0) -> -10898 | L5: =IF(ISERROR(K5),J5,J5+K5) -> 0 | N5: Abby Leaf Inc Licorish Gumball dried flower Grade A | O5: -10898
A6: 4:1 Black Cherry CBD:THC extract 29.5g | B6: 24 | C6: =VLOOKUP(A6,F:G,2,0) -> #N/A | D6: =IF(ISERROR(C6),B6,B6+C6) -> 24 | F6: Apothecary Botanicals Gelato 14g dried flower | G6: -60 | I6: Abby Leaf Inc Licorish Gumball dried flower Grade B | J6: 6122 | K6: =VLOOKUP(I6,N:O,2,0) -> -6122 | L6: =IF(ISERROR(K6),J6,J6+K6) -> 0 | N6: Abby Leaf Inc Licorish Gumball dried flower Grade B | O6: -6122
A7: Afghan Hash 1g | B7: 21 | C7: =VLOOKUP(A7,F:G,2,0) -> #N/A | D7: =IF(ISERROR(C7),B7,B7+C7) -> 21 | F7: Aum CBD oil 27.4g | G7: -703 | I7: Abby Leaf Inc Unicorn Poop Grade A | J7: 9072 | K7: =VLOOKUP(I7,N:O,2,0) -> -9070 | L7: =IF(ISERROR(K7),J7,J7+K7) -> 2 | N7: Abby Leaf Inc Unicorn Poop Grade A | O7: -9070
A8: Animal Cookies dried flower 3.5 g | B8: 66 | C8: =VLOOKUP(A8,F:G,2,0) -> #N/A | D8: =IF(ISERROR(C8),B8,B8+C8) -> 66 | F8: Bacon CBD extract 27.3g | G8: -70 | I8: Abby Leaf Inc Unicorn Poop Grade B | J8: 3930 | K8: =VLOOKUP(I8,N:O,2,0) -> -3932 | L8: =IF(ISERROR(K8),J8,J8+K8) -> -2 | N8: Abby Leaf Inc Unicorn Poop Grade B | O8: -3932
A9: Animal Mint pre-roll 2 x 1g | B9: 2639 | C9: =VLOOKUP(A9,F:G,2,0) -> -2646 | D9: =IF(ISERROR(C9),B9,B9+C9) -> -7 | F9: Bacon CBD Extract 27.6g | G9: -127 | I9: Animal Mint dried flower | J9: 7565 | K9: =VLOOKUP(I9,N:O,2,0) -> -655 | L9: =IF(ISERROR(K9),J9,J9+K9) -> 6910 | N9: Animal Mint dried flower | O9: -655
A10: Apothecary Botanicals Gelato 14g dried flower | B10: 60 | C10: =VLOOKUP(A10,F:G,2,0) -> -60 | D10: =IF(ISERROR(C10),B10,B10+C10) -> 0 | F10: Bacon CBD extract 54.8g | G10: -3 | I10: Animal Mint milled flower | J10: 10340 | K10: =VLOOKUP(I10,N:O,2,0) -> -28332 | L10: =IF(ISERROR(K10),J10,J10+K10) -> -17992 | N10: Animal Mint milled flower | O10: -28332
A11: Aum CBD oil 27.4g | B11: 442 | C11: =VLOOKUP(A11,F:G,2,0) -> -703 | D11: =IF(ISERROR(C11),B11,B11+C11) -> -261 | F11: bath salt SPA 180 gram | G11: -220 | I11: Atlas trims | J11: 4152 | K11: =VLOOKUP(I11,N:O,2,0) -> #N/A | L11: =IF(ISERROR(K11),J11,J11+K11) -> 4152 | N11: Bacon CBD Extract | O11: -13470
A12: Backforty Blends Glacial Gold Clay Face Mask | B12: 550 | C12: =VLOOKUP(A12,F:G,2,0) -> #N/A | D12: =IF(ISERROR(C12),B12,B12+C12) -> 550 | F12: Blue Gum Dried Flower 28g | G12: -108 | I12: Bacon CBD Extract | J12: 61265 | K12: =VLOOKUP(I12,N:O,2,0) -> -13470 | L12: =IF(ISERROR(K12),J12,J12+K12) -> 47795 | N12: bath salt SPA 180 gram | O12: -71400
A13: Bacon CBD extract 27.3g | B13: 72 | C13: =VLOOKUP(A13,F:G,2,0) -> -70 | D13: =IF(ISERROR(C13),B13,B13+C13) -> 2 | F13: Blueberry Punch Bubble Hash 1g | G13: -353 | I13: bath salt SPA 180 gram | J13: 71400 | K13: =VLOOKUP(I13,N:O,2,0) -> -71400 | L13: =IF(ISERROR(K13),J13,J13+K13) -> 0 | N13: Blue Bandita Live Rosin | O13: -3905
A14: Bacon CBD Extract 27.6g | B14: 136 | C14: =VLOOKUP(A14,F:G,2,0) -> -127 | D14: =IF(ISERROR(C14),B14,B14+C14) -> 9 | F14: CBD Bacon Oil 10 mg 27.3g | G14: -629 | I14: Berri Blunt milled flower | J14: 88.04 | K14: =VLOOKUP(I14,N:O,2,0) -> #N/A | L14: =IF(ISERROR(K14),J14,J14+K14) -> 88.04 | N14: Blue Gum Dried Flower | O14: -27440
A15: Bacon CBD extract 29.5g | B15: 9 | C15: =VLOOKUP(A15,F:G,2,0) -> #N/A | D15: =IF(ISERROR(C15),B15,B15+C15) -> 9 | F15: CBD Neem Cream 120g | G15: -60 | I15: Blue Bandita Live Rosin | J15: 3905 | K15: =VLOOKUP(I15,N:O,2,0) -> -3905 | L15: =IF(ISERROR(K15),J15,J15+K15) -> 0 | N15: Blue Gum Dried Flower Grade A | O15: -14058
A16: Bacon CBD extract 54.8g | B16: 20 | C16: =VLOOKUP(A16,F:G,2,0) -> -3 | D16: =IF(ISERROR(C16),B16,B16+C16) -> 17 | F16: Chronic Mint preroll 1 x 1g | G16: -12 | I16: Blue Gum Dried Flower | J16: 27440 | K16: =VLOOKUP(I16,N:O,2,0) -> -27440 | L16: =IF(ISERROR(K16),J16,J16+K16) -> 0 | N16: Canadian Thunder Rosin Vape | O16: -2355.54
... A62: Grease Monkey preroll 1 x 1g | B62: 206 | C62: =VLOOKUP(A62,F:G,2,0) -> -72 | D62: =IF(ISERROR(C62),B62,B62+C62) -> 134 | F62: November Rain Blaster Multipack 0.5g*12 | G62: -1027 | I62: Pressure Pie dried flower | J62: 16541 | K62: =VLOOKUP(I62,N:O,2,0) -> -16199 | L62: =IF(ISERROR(K62),J62,J62+K62) -> 342 | N62: Grand Total | O62: -975335.28
A63: Grease Monkey preroll 1g | B63: 537 | C63: =VLOOKUP(A63,F:G,2,0) -> #N/A | D63: =IF(ISERROR(C63),B63,B63+C63) -> 537 | F63: November Rain Blueberry preroll 0.5g | G63: -9783 | I63: Pressure Pie milled flower | J63: 2386 | K63: =VLOOKUP(I63,N:O,2,0) -> -6622 | L63: =IF(ISERROR(K63),J63,J63+K63) -> -4236
A64: Grease Monkey preroll 3 x 0.5g | B64: 759 | C64: =VLOOKUP(A64,F:G,2,0) -> -849 | D64: =IF(ISERROR(C64),B64,B64+C64) -> -90 | F64: November Rain Blueberry preroll 3 x 0.5g | G64: -3406 | I64: Rockstar dried flower | J64: 61218 | K64: =VLOOKUP(I64,N:O,2,0) -> -41549 | L64: =IF(ISERROR(K64),J64,J64+K64) -> 19669
A65: Hara milled flower 14g | B65: 404 | C65: =VLOOKUP(A65,F:G,2,0) -> -404 | D65: =IF(ISERROR(C65),B65,B65+C65) -> 0 | F65: November Rain Concord Grape vape 0.5g | G65: -557 | I65: Rockstar milled flower | J65: 15426 | K65: =VLOOKUP(I65,N:O,2,0) -> -11059 | L65: =IF(ISERROR(K65),J65,J65+K65) -> 4367
A66: Hara milled flower 7g | B66: 106 | C66: =VLOOKUP(A66,F:G,2,0) -> -106 | D66: =IF(ISERROR(C66),B66,B66+C66) -> 0 | F66: November Rain Concord Grape vape 1g | G66: -145 | I66: Rogue milled flower | J66: 0 | K66: =VLOOKUP(I66,N:O,2,0) -> #N/A | L66: =IF(ISERROR(K66),J66,J66+K66) -> 0
A67: Infused preroll | B67: 104 | C67: =VLOOKUP(A67,F:G,2,0) -> #N/A | D67: =IF(ISERROR(C67),B67,B67+C67) -> 104 | F67: November Rain Gastro-pop Diamond Infused 3x0.5g Pre-Rolls | G67: -1010 | I67: Runtz Muffin Crumble (Rohan) | J67: 8583 | K67: =VLOOKUP(I67,N:O,2,0) -> -2437 | L67: =IF(ISERROR(K67),J67,J67+K67) -> 6146
A68: Infused preroll 1 x 1g | B68: 87 | C68: =VLOOKUP(A68,F:G,2,0) -> -12 | D68: =IF(ISERROR(C68),B68,B68+C68) -> 75 | F68: November Rain Lemon Ice Tea preroll 0.5g | G68: -992 | I68: Spotlight Vape | J68: 1092.42 | K68: =VLOOKUP(I68,N:O,2,0) -> #N/A | L68: =IF(ISERROR(K68),J68,J68+K68) -> 1092.42
A69: Infused preroll 1g | B69: 1625 | C69: =VLOOKUP(A69,F:G,2,0) -> -200 | D69: =IF(ISERROR(C69),B69,B69+C69) -> 1425 | F69: November Rain Lemon Ice Tea preroll 3 x 0.5g | G69: -1152 | I69: Strawberry Drizzle Vape | J69: 5516.58 | K69: =VLOOKUP(I69,N:O,2,0) -> -3364.95 | L69: =IF(ISERROR(K69),J69,J69+K69) -> 2151.63
A70: Infused preroll 3 x 0.5g | B70: 268 | C70: =VLOOKUP(A70,F:G,2,0) -> #N/A | D70: =IF(ISERROR(C70),B70,B70+C70) -> 268 | F70: November Rain Preroll Rose Mintz 3x0.5g | G70: -120 | I70: Super Sativa Oil | J70: 33155 | K70: =VLOOKUP(I70,N:O,2,0) -> -33155 | L70: =IF(ISERROR(K70),J70,J70+K70) -> 0
A71: Island KTL Live Resin 1g | B71: 170 | C71: =VLOOKUP(A71,F:G,2,0) -> -169 | D71: =IF(ISERROR(C71),B71,B71+C71) -> 1 | F71: November Rain Rose preroll 0.5g | G71: -4052 | I71: THC CBD balanced 1:1 oil | J71: 3995 | K71: =VLOOKUP(I71,N:O,2,0) -> -3990 | L71: =IF(ISERROR(K71),J71,J71+K71) -> 5
A72: Island Pink dried flower | B72: 0 | C72: =VLOOKUP(A72,F:G,2,0) -> #N/A | D72: =IF(ISERROR(C72),B72,B72+C72) -> 0 | F72: November Rain Rose preroll 3 x 0.5g | G72: -2128 | I72: THC Distillate | J72: 16952.39 | K72: =VLOOKUP(I72,N:O,2,0) -> -16025.49 | L72: =IF(ISERROR(K72),J72,J72+K72) -> 926.9
A73: Licorice Gumball dried flower 14g | B73: 1560 | C73: =VLOOKUP(A73,F:G,2,0) -> -1560 | D73: =IF(ISERROR(C73),B73,B73+C73) -> 0 | F73: November Rain Trident preroll 3 x 0.5g | G73: -2426 | I73: THC oil | J73: 4150 | K73: =VLOOKUP(I73,N:O,2,0) -> -4150 | L73: =IF(ISERROR(K73),J73,J73+K73) -> 0
A74: Licorice Gumball pre-roll 5 x 0.5g | B74: 24 | C74: =VLOOKUP(A74,F:G,2,0) -> #N/A | D74: =IF(ISERROR(C74),B74,B74+C74) -> 24 | F74: November Rain Vape Canadian OG | G74: -120 | I74: THCA Diamond | J74: 2304 | K74: =VLOOKUP(I74,N:O,2,0) -> -746.87 | L74: =IF(ISERROR(K74),J74,J74+K74) -> 1557.13
... A86: November Rain Blaster Multipack 0.5g*12 | B86: 1007 | C86: =VLOOKUP(A86,F:G,2,0) -> -1027 | D86: =IF(ISERROR(C86),B86,B86+C86) -> -20 | F86: Pineapple Sour preroll 1g | G86: -85 | I86: Grand Total | J86: 1163512 | K86: =VLOOKUP(I86,N:O,2,0) -> -975335.28 | L86: =IF(ISERROR(K86),J86,J86+K86) -> 188176.74
A87: November Rain Blueberry preroll 0.5g | B87: 8696 | C87: =VLOOKUP(A87,F:G,2,0) -> -9783 | D87: =IF(ISERROR(C87),B87,B87+C87) -> -1087 | F87: Pot Shot Citrus 151mg | G87: -1366 | K87: =VLOOKUP(I87,N:O,2,0) -> #N/A | L87: =IF(ISERROR(K87),J87,J87+K87) -> 0
A88: November Rain Blueberry preroll 3 x 0.5g | B88: 2869 | C88: =VLOOKUP(A88,F:G,2,0) -> -3406 | D88: =IF(ISERROR(C88),B88,B88+C88) -> -537 | F88: Pot Shot Coconut Lime 151mg | G88: -751 | K88: =VLOOKUP(I88,N:O,2,0) -> #N/A | L88: =IF(ISERROR(K88),J88,J88+K88) -> 0
A89: November Rain Concord Grape vape 0.5g | B89: 967 | C89: =VLOOKUP(A89,F:G,2,0) -> -557 | D89: =IF(ISERROR(C89),B89,B89+C89) -> 410 | F89: Pot Shot Tropical Fruits 151mg | G89: -2406 | K89: =VLOOKUP(I89,N:O,2,0) -> #N/A | L89: =IF(ISERROR(K89),J89,J89+K89) -> 0
A90: November Rain Concord Grape vape 1g | B90: 142 | C90: =VLOOKUP(A90,F:G,2,0) -> -145 | D90: =IF(ISERROR(C90),B90,B90+C90) -> -3 | F90: Pressure Pie dried flower 28g | G90: -156 | K90: =VLOOKUP(I90,N:O,2,0) -> #N/A | L90: =IF(ISERROR(K90),J90,J90+K90) -> 0
A91: November Rain Gastro-pop Diamond Infused 3x0.5g Pre-Rolls | B91: 1567 | C91: =VLOOKUP(A91,F:G,2,0) -> -1010 | D91: =IF(ISERROR(C91),B91,B91+C91) -> 557 | F91: Rogworld Lemonade Octane vape 1g | G91: -630 | K91: =VLOOKUP(I91,N:O,2,0) -> #N/A | L91: =IF(ISERROR(K91),J91,J91+K91) -> 0
A92: November Rain Infused blueberry preroll 3*0.5g | B92: 11 | C92: =VLOOKUP(A92,F:G,2,0) -> #N/A | D92: =IF(ISERROR(C92),B92,B92+C92) -> 11 | F92: Rogworld-Bong Guru Rockstar-14g | G92: -55 | K92: =VLOOKUP(I92,N:O,2,0) -> #N/A | L92: =IF(ISERROR(K92),J92,J92+K92) -> 0
A93: November Rain Lemon Ice Tea preroll 0.5g | B93: 992 | C93: =VLOOKUP(A93,F:G,2,0) -> -992 | D93: =IF(ISERROR(C93),B93,B93+C93) -> 0 | F93: Rogworld-Bong Guru Rockstar-1g pre-roll | G93: -12 | K93: =VLOOKUP(I93,N:O,2,0) -> #N/A | L93: =IF(ISERROR(K93),J93,J93+K93) -> 0
A94: November Rain Lemon Ice Tea preroll 3 x 0.5g | B94: 1529 | C94: =VLOOKUP(A94,F:G,2,0) -> -1152 | D94: =IF(ISERROR(C94),B94,B94+C94) -> 377 | F94: Rogworld-Bong Guru Rockstar-5X0.5g pre-rolls | G94: -396 | K94: =VLOOKUP(I94,N:O,2,0) -> #N/A | L94: =IF(ISERROR(K94),J94,J94+K94) -> 0
A95: November Rain Preroll Rose Mintz 3x0.5g | B95: 168 | C95: =VLOOKUP(A95,F:G,2,0) -> -120 | D95: =IF(ISERROR(C95),B95,B95+C95) -> 48 | F95: Romulan Grape God Bubble Hash 1g | G95: -36 | K95: =VLOOKUP(I95,N:O,2,0) -> #N/A | L95: =IF(ISERROR(K95),J95,J95+K95) -> 0
A96: November Rain Rose preroll 0.5g | B96: 4169 | C96: =VLOOKUP(A96,F:G,2,0) -> -4052 | D96: =IF(ISERROR(C96),B96,B96+C96) -> 117 | F96: Rose Diamond Infused preroll 3x0.5g | G96: -48 | K96: =VLOOKUP(I96,N:O,2,0) -> #N/A | L96: =IF(ISERROR(K96),J96,J96+K96) -> 0
A97: November Rain Rose preroll 3 x 0.5g | B97: 1166 | C97: =VLOOKUP(A97,F:G,2,0) -> -2128 | D97: =IF(ISERROR(C97),B97,B97+C97) -> -962 | F97: Runtz Muffin Crumble (Rohan) | G97: -119 | K97: =VLOOKUP(I97,N:O,2,0) -> #N/A | L97: =IF(ISERROR(K97),J97,J97+K97) -> 0
...

Sheet cannabis_log
A1: inventory_id_head | B1: inventory_id_tail | C1: inventory_id | D1: status | E1: tote_number | F1: bag_number | G1: location | H1: stage | I1: product_description | J1: lot_number | K1: pack_on_date | L1: number_of_unit | M1: unit | N1: net_weight_per_unit | O1: gross_weight | P1: tare_weight | Q1: quantity_gram | R1: note | S1: time | T1: calculation_method | U1: product_description_stage | V1: internal_cansku
A2: 576 | B2: 0 | C2: =Table1[[#This Row],[inventory_id_head]]&"-"&Table1[[#This Row],[inventory_id_tail]] -> 576-0 | D2: Active | E2: T118EX | F2: NA | G2: =E2&F2 -> T118EXNA | H2: extract_inhaled_packaged | J2: EX24111301G05 | K2: 45642 | L2: 626 | M2: unit | N2: 0.5 | O2: 0 | P2: 0 | Q2: =L2*N2 -> 313 | S2: 45293.572 | T2: net | U2: =I2&"_"&H2 -> _extract_inhaled_packaged | V2: =IF(U2="_","",_xlfn.XLOOKUP(U2,internal_cansku_inventory!D:D,internal_cansku_inventory!E:E,"",0,1))
A3: 577 | B3: 0 | C3: =Table1[[#This Row],[inventory_id_head]]&"-"&Table1[[#This Row],[inventory_id_tail]] -> 577-0 | D3: Active | E3: T013TP | F3: NA | G3: =E3&F3 -> T013TPNA | H3: topical_labelled | J3: TP24120401G45 | K3: 45638 | L3: 300 | M3: unit | N3: 45 | O3: 0 | P3: 0 | Q3: =L3*N3 -> 13500 | S3: 45293.572 | T3: net | U3: =I3&"_"&H3 -> _topical_labelled | V3: =IF(U3="_","",_xlfn.XLOOKUP(U3,internal_cansku_inventory!D:D,internal_cansku_inventory!E:E,"",0,1))
A4: 578 | B4: 0 | C4: =Table1[[#This Row],[inventory_id_head]]&"-"&Table1[[#This Row],[inventory_id_tail]] -> 578-0 | D4: Active | E4: T014TP | F4: NA | G4: =E4&F4 -> T014TPNA | H4: topical_labelled | J4: TP24120401G45 | K4: 45638 | L4: 300 | M4: unit | N4: 45 | O4: 0 | P4: 0 | Q4: =L4*N4 -> 13500 | S4: 45293.572 | T4: net | U4: =I4&"_"&H4 -> _topical_labelled | V4: =IF(U4="_","",_xlfn.XLOOKUP(U4,internal_cansku_inventory!D:D,internal_cansku_inventory!E:E,"",0,1))
A5: 579 | B5: 0 | C5: =Table1[[#This Row],[inventory_id_head]]&"-"&Table1[[#This Row],[inventory_id_tail]] -> 579-0 | D5: Active | E5: P012TP | F5: NA | G5: =E5&F5 -> P012TPNA | H5: topical_bulk | J5: TP24120401 | K5: NA | L5: 1 | M5: pail | N5: =Table1[[#This Row],[gross_weight]]-Table1[[#This Row],[tare_weight]] -> 23062 | O5: 24830 | P5: =24830-23062 -> 1768 | Q5: =L5*N5 -> 23062 | S5: 45293.572 | T5: gross | U5: =I5&"_"&H5 -> _topical_bulk | V5: =IF(U5="_","",_xlfn.XLOOKUP(U5,internal_cansku_inventory!D:D,internal_cansku_inventory!E:E,"",0,1))
A6: 580 | B6: 0 | C6: =Table1[[#This Row],[inventory_id_head]]&"-"&Table1[[#This Row],[inventory_id_tail]] -> 580-0 | D6: Active | E6: P013TP | F6: NA | G6: =E6&F6 -> P013TPNA | H6: topical_bulk | J6: TP24120401 | K6: NA | L6: 1 | M6: pail | N6: =Table1[[#This Row],[gross_weight]]-Table1[[#This Row],[tare_weight]] -> 5192 | O6: 7130 | P6: =7130-5192 -> 1938 | Q6: =L6*N6 -> 5192 | S6: 45293.572 | T6: gross | U6: =I6&"_"&H6 -> _topical_bulk | V6: =IF(U6="_","",_xlfn.XLOOKUP(U6,internal_cansku_inventory!D:D,internal_cansku_inventory!E:E,"",0,1))
A7: 581 | B7: 0 | C7: =Table1[[#This Row],[inventory_id_head]]&"-"&Table1[[#This Row],[inventory_id_tail]] -> 581-0 | D7: Active | E7: P014TP | F7: NA | G7: =E7&F7 -> P014TPNA | H7: topical_bulk | J7: TP24120401 | K7: NA | L7: 1 | M7: pail | N7: =Table1[[#This Row],[gross_weight]]-Table1[[#This Row],[tare_weight]] -> 22994 | O7: 24750 | P7: =24750-22994 -> 1756 | Q7: =L7*N7 -> 22994 | S7: 45293.572 | T7: gross | U7: =I7&"_"&H7 -> _topical_bulk | V7: =IF(U7="_","",_xlfn.XLOOKUP(U7,internal_cansku_inventory!D:D,internal_cansku_inventory!E:E,"",0,1))
A8: 582 | B8: 0 | C8: =Table1[[#This Row],[inventory_id_head]]&"-"&Table1[[#This Row],[inventory_id_tail]] -> 582-0 | D8: Active | E8: P015TP | F8: NA | G8: =E8&F8 -> P015TPNA | H8: topical_bulk | J8: TP24120401 | K8: NA | L8: 1 | M8: pail | N8: =Table1[[#This Row],[gross_weight]]-Table1[[#This Row],[tare_weight]] -> 1756 | O8: 26400 | P8: 24644 | Q8: =L8*N8 -> 1756 | S8: 45293.572 | T8: gross | U8: =I8&"_"&H8 -> _topical_bulk | V8: =IF(U8="_","",_xlfn.XLOOKUP(U8,internal_cansku_inventory!D:D,internal_cansku_inventory!E:E,"",0,1))
A9: 583 | B9: 0 | C9: =Table1[[#This Row],[inventory_id_head]]&"-"&Table1[[#This Row],[inventory_id_tail]] -> 583-0 | D9: Active | E9: P016TP | F9: NA | G9: =E9&F9 -> P016TPNA | H9: topical_bulk | J9: TP24120401 | K9: NA | L9: 1 | M9: pail | N9: =Table1[[#This Row],[gross_weight]]-Table1[[#This Row],[tare_weight]] -> 1754 | O9: 26055 | P9: 24301 | Q9: =L9*N9 -> 1754 | S9: 45293.572 | T9: gross | U9: =I9&"_"&H9 -> _topical_bulk | V9: =IF(U9="_","",_xlfn.XLOOKUP(U9,internal_cansku_inventory!D:D,internal_cansku_inventory!E:E,"",0,1))
A10: 585 | B10: 0 | C10: =Table1[[#This Row],[inventory_id_head]]&"-"&Table1[[#This Row],[inventory_id_tail]] -> 585-0 | D10: Active | E10: T015TP | F10: NA | G10: =E10&F10 -> T015TPNA | H10: topical_labelled | J10: TP24120401G45 | K10: 45638 | L10: 300 | M10: unit | N10: 45 | O10: 0 | P10: 0 | Q10: =L10*N10 -> 13500 | S10: 45293.665 | T10: net | U10: =I10&"_"&H10 -> _topical_labelled | V10: =IF(U10="_","",_xlfn.XLOOKUP(U10,internal_cansku_inventory!D:D,internal_cansku_inventory!E:E,"",0,1))
A11: 586 | B11: 0 | C11: =Table1[[#This Row],[inventory_id_head]]&"-"&Table1[[#This Row],[inventory_id_tail]] -> 586-0 | D11: Active | E11: T016TP | F11: NA | G11: =E11&F11 -> T016TPNA | H11: topical_labelled | J11: TP24120401G45 | K11: 45638 | L11: 138 | M11: unit | N11: 45 | O11: 0 | P11: 0 | Q11: =L11*N11 -> 6210 | S11: 45293.665 | T11: net | U11: =I11&"_"&H11 -> _topical_labelled | V11: =IF(U11="_","",_xlfn.XLOOKUP(U11,internal_cansku_inventory!D:D,internal_cansku_inventory!E:E,"",0,1))
A12: 587 | B12: 0 | C12: =Table1[[#This Row],[inventory_id_head]]&"-"&Table1[[#This Row],[inventory_id_tail]] -> 587-0 | D12: Active | E12: B001DF | F12: NA | G12: =E12&F12 -> B001DFNA | H12: driedflower_bulk_BURB | J12: 2025010201 | K12: NA | L12: 1 | M12: bag | N12: =Table1[[#This Row],[gross_weight]]-Table1[[#This Row],[tare_weight]] -> 4360 | O12: 4670 | P12: =4670-4360 -> 310 | Q12: =L12*N12 -> 4360 | R12: high potency_14g central | S12: 45293.665 | T12: gross | U12: =I12&"_"&H12 -> _driedflower_bulk_BURB | V12: =IF(U12="_","",_xlfn.XLOOKUP(U12,internal_cansku_inventory!D:D,internal_cansku_inventory!E:E,"",0,1))
A13: 588 | B13: 0 | C13: =Table1[[#This Row],[inventory_id_head]]&"-"&Table1[[#This Row],[inventory_id_tail]] -> 588-0 | D13: Active | E13: B002DF | F13: NA | G13: =E13&F13 -> B002DFNA | H13: driedflower_bulk_BURB | J13: 2025010201 | K13: NA | L13: 1 | M13: bag | N13: =Table1[[#This Row],[gross_weight]]-Table1[[#This Row],[tare_weight]] -> 4360 | O13: 4670 | P13: =4670-4360 -> 310 | Q13: =L13*N13 -> 4360 | R13: high potency_14g central | S13: 45293.665 | T13: gross | U13: =I13&"_"&H13 -> _driedflower_bulk_BURB | V13: =IF(U13="_","",_xlfn.XLOOKUP(U13,internal_cansku_inventory!D:D,internal_cansku_inventory!E:E,"",0,1))
A14: 589 | B14: 0 | C14: =Table1[[#This Row],[inventory_id_head]]&"-"&Table1[[#This Row],[inventory_id_tail]] -> 589-0 | D14: Active | E14: B003DF | F14: NA | G14: =E14&F14 -> B003DFNA | H14: driedflower_bulk_BURB | J14: 2025010201 | K14: NA | L14: 1 | M14: bag | N14: 4360 | O14: 4665 | P14: 305 | Q14: =L14*N14 -> 4360 | R14: high potency_14g central | S14: 45293.665 | T14: gross | U14: =I14&"_"&H14 -> _driedflower_bulk_BURB | V14: =IF(U14="_","",_xlfn.XLOOKUP(U14,internal_cansku_inventory!D:D,internal_cansku_inventory!E:E,"",0,1))
A15: 590 | B15: 0 | C15: =Table1[[#This Row],[inventory_id_head]]&"-"&Table1[[#This Row],[inventory_id_tail]] -> 590-0 | D15: Active | E15: B004DF | F15: NA | G15: =E15&F15 -> B004DFNA | H15: driedflower_bulk_BURB | J15: 2025010201 | K15: NA | L15: 1 | M15: bag | N15: =Table1[[#This Row],[gross_weight]]-Table1[[#This Row],[tare_weight]] -> 4360 | O15: 4665 | P15: 305 | Q15: =L15*N15 -> 4360 | R15: high potency_14g central | S15: 45293.665 | T15: gross | U15: =I15&"_"&H15 -> _driedflower_bulk_BURB | V15: =IF(U15="_","",_xlfn.XLOOKUP(U15,internal_cansku_inventory!D:D,internal_cansku_inventory!E:E,"",0,1))
A16: 591 | B16: 0 | C16: =Table1[[#This Row],[inventory_id_head]]&"-"&Table1[[#This Row],[inventory_id_tail]] -> 591-0 | D16: Active | E16: B005DF | F16: NA | G16: =E16&F16 -> B005DFNA | H16: driedflower_bulk_BURB | J16: 2025010201 | K16: NA | L16: 1 | M16: bag | N16: =Table1[[#This Row],[gross_weight]]-Table1[[#This Row],[tare_weight]] -> 4360 | O16: 4670 | P16: =4670-4360 -> 310 | Q16: =L16*N16 -> 4360 | R16: high potency_14g central_small flower | S16: 45293.665 | T16: gross | U16: =I16&"_"&H16 -> _driedflower_bulk_BURB | V16: =IF(U16="_","",_xlfn.XLOOKUP(U16,internal_cansku_inventory!D:D,internal_cansku_inventory!E:E,"",0,1))
A17: 440 | B17: 0 | C17: =Table1[[#This Row],[inventory_id_head]]&"-"&Table1[[#This Row],[inventory_id_tail]] -> 440-0 | D17: Closed | E17: NA | F17: NA | G17: OFDMB | H17: extract_ingested_cased_MB | J17: EX24022302V30 | K17: 45588 | L17: 8 | M17: case | N17: =29.3*12 -> 351.6 | O17: 0 | P17: 0 | Q17: =L17*N17 -> 2812.8 | S17: 45297.408 | T17: net | U17: =I17&"_"&H17 -> _extract_ingested_cased_MB | V17: =IF(U17="_","",_xlfn.XLOOKUP(U17,internal_cansku_inventory!D:D,internal_cansku_inventory!E:E,"",0,1))
A18: 3 | B18: 0 | C18: =Table1[[#This Row],[inventory_id_head]]&"-"&Table1[[#This Row],[inventory_id_tail]] -> 3-0 | D18: Active | E18: T001ED | F18: NA | G18: =E18&F18 -> T001EDNA | H18: extract_inhaled_packaged | J18: PE2205CP085D | K18: NA | L18: 99 | M18: jar | N18: 1 | O18: 0 | P18: 0 | Q18: =L18*N18 -> 99 | R18: Unlabelled | S18: 45484 | T18: net | U18: =I18&"_"&H18 -> _extract_inhaled_packaged | V18: =IF(U18="_","",_xlfn.XLOOKUP(U18,internal_cansku_inventory!D:D,internal_cansku_inventory!E:E,"",0,1))
A19: 5 | B19: 0 | C19: =Table1[[#This Row],[inventory_id_head]]&"-"&Table1[[#This Row],[inventory_id_tail]] -> 5-0 | D19: Active | E19: T001DF | F19: NA | G19: =E19&F19 -> T001DFNA | H19: driedflower_packaged | J19: 211007 | K19: 44495 | L19: 66 | M19: jar | N19: 3.5 | O19: 0 | P19: 0 | Q19: =L19*N19 -> 231 | S19: 45484 | T19: net | U19: =I19&"_"&H19 -> _driedflower_packaged | V19: =IF(U19="_","",_xlfn.XLOOKUP(U19,internal_cansku_inventory!D:D,internal_cansku_inventory!E:E,"",0,1))
A20: 6 | B20: 0 | C20: =Table1[[#This Row],[inventory_id_head]]&"-"&Table1[[#This Row],[inventory_id_tail]] -> 6-0 | D20: Active | E20: T002DF | F20: NA | G20: =E20&F20 -> T002DFNA | H20: driedflower_packaged | J20: 2022042902 | K20: NA | L20: 156 | M20: jar | N20: 3.5 | O20: 0 | P20: 0 | Q20: =L20*N20 -> 546 | R20: Unlabelled | S20: 45484 | T20: net | U20: =I20&"_"&H20 -> _driedflower_packaged | V20: =IF(U20="_","",_xlfn.XLOOKUP(U20,internal_cansku_inventory!D:D,internal_cansku_inventory!E:E,"",0,1))
A21: 7 | B21: 0 | C21: =Table1[[#This Row],[inventory_id_head]]&"-"&Table1[[#This Row],[inventory_id_tail]] -> 7-0 | D21: Active | E21: T003DF | F21: NA | G21: =E21&F21 -> T003DFNA | H21: driedflower_packaged | J21: 2022042902 | K21: NA | L21: 319 | M21: jar | N21: 3.5 | O21: 0 | P21: 0 | Q21: =L21*N21 -> 1116.5 | R21: Unlabelled | S21: 45484 | T21: net | U21: =I21&"_"&H21 -> _driedflower_packaged | V21: =IF(U21="_","",_xlfn.XLOOKUP(U21,internal_cansku_inventory!D:D,internal_cansku_inventory!E:E,"",0,1))
A22: 8 | B22: 0 | C22: =Table1[[#This Row],[inventory_id_head]]&"-"&Table1[[#This Row],[inventory_id_tail]] -> 8-0 | D22: Active | E22: T004DF | F22: NA | G22: =E22&F22 -> T004DFNA | H22: driedflower_packaged | J22: 2022012401R1 | K22: 45100 | L22: 82 | M22: pouch | N22: 14 | O22: 0 | P22: 0 | Q22: =L22*N22 -> 1148 | S22: 45484 | T22: net | U22: =I22&"_"&H22 -> _driedflower_packaged | V22: =IF(U22="_","",_xlfn.XLOOKUP(U22,internal_cansku_inventory!D:D,internal_cansku_inventory!E:E,"",0,1))
A23: 9 | B23: 0 | C23: =Table1[[#This Row],[inventory_id_head]]&"-"&Table1[[#This Row],[inventory_id_tail]] -> 9-0 | D23: Active | E23: T001MF | F23: NA | G23: =E23&F23 -> T001MFNA | H23: driedflower_milled_labelled | J23: CPR22112801G14 | K23: 44941 | L23: 404 | M23: pouch | N23: 14 | O23: 0 | P23: 0 | Q23: =L23*N23 -> 5656 | R23: AB stamped | S23: 45484 | T23: net | U23: =I23&"_"&H23 -> _driedflower_milled_labelled | V23: =IF(U23="_","",_xlfn.XLOOKUP(U23,internal_cansku_inventory!D:D,internal_cansku_inventory!E:E,"",0,1))
A24: 10 | B24: 0 | C24: =Table1[[#This Row],[inventory_id_head]]&"-"&Table1[[#This Row],[inventory_id_tail]] -> 10-0 | D24: Active | E24: T002MF | F24: NA | G24: =E24&F24 -> T002MFNA | H24: driedflower_milled_labelled | J24: CPR22112801G7 | K24: 44941 | L24: 106 | M24: pouch | N24: 7 | O24: 0 | P24: 0 | Q24: =L24*N24 -> 742 | S24: 45484 | T24: net | U24: =I24&"_"&H24 -> _driedflower_milled_labelled | V24: =IF(U24="_","",_xlfn.XLOOKUP(U24,internal_cansku_inventory!D:D,internal_cansku_inventory!E:E,"",0,1))
A25: 12 | B25: 0 | C25: =Table1[[#This Row],[inventory_id_head]]&"-"&Table1[[#This Row],[inventory_id_tail]] -> 12-0 | D25: Active | E25: T003MF | F25: B001MF | G25: =E25&F25 -> T003MFB001MF | H25: driedflower_milled_bulk | J25: PR2303IN | K25: 45253 | L25: 1 | M25: bag | N25: 41.02 | O25: 0 | P25: 0 | Q25: =L25*N25 -> 41.02 | S25: 45484 | T25: gross | U25: =I25&"_"&H25 -> _driedflower_milled_bulk | V25: =IF(U25="_","",_xlfn.XLOOKUP(U25,internal_cansku_inventory!D:D,internal_cansku_inventory!E:E,"",0,1))
A26: 13 | B26: 0 | C26: =Table1[[#This Row],[inventory_id_head]]&"-"&Table1[[#This Row],[inventory_id_tail]] -> 13-0 | D26: Active | E26: T003MF | F26: B002MF | G26: =E26&F26 -> T003MFB002MF | H26: driedflower_milled_bulk | J26: CPR22102101 | K26: NA | L26: 1 | M26: bag | N26: 169.94 | O26: 179.18 | P26: 9.24 | Q26: =L26*N26 -> 169.94 | S26: 45484 | T26: gross | U26: =I26&"_"&H26 -> _driedflower_milled_bulk | V26: =IF(U26="_","",_xlfn.XLOOKUP(U26,internal_cansku_inventory!D:D,internal_cansku_inventory!E:E,"",0,1))
A27: 14 | B27: 0 | C27: =Table1[[#This Row],[inventory_id_head]]&"-"&Table1[[#This Row],[inventory_id_tail]] -> 14-0 | D27: Active | E27: T003MF | F27: B003MF | G27: =E27&F27 -> T003MFB003MF | H27: driedflower_milled_bulk | J27: PR2304F7 | K27: NA | L27: 1 | M27: bag | N27: 72.83 | O27: 88.04 | P27: =O27-N27 -> 15.21 | Q27: =L27*N27 -> 72.83 | S27: 45484 | T27: gross | U27: =I27&"_"&H27 -> _driedflower_milled_bulk | V27: =IF(U27="_","",_xlfn.XLOOKUP(U27,internal_cansku_inventory!D:D,internal_cansku_inventory!E:E,"",0,1))
A28: 15 | B28: 0 | C28: =Table1[[#This Row],[inventory_id_head]]&"-"&Table1[[#This Row],[inventory_id_tail]] -> 15-0 | D28: Active | E28: T003MF | F28: B004MF | G28: =E28&F28 -> T003MFB004MF | H28: driedflower_milled_bulk | J28: NA | K28: NA | L28: 1 | M28: bag | N28: 904.95 | O28: 0 | P28: 0 | Q28: =L28*N28 -> 904.95 | R28: unknown lot | S28: 45484 | T28: gross | U28: =I28&"_"&H28 -> _driedflower_milled_bulk | V28: =IF(U28="_","",_xlfn.XLOOKUP(U28,internal_cansku_inventory!D:D,internal_cansku_inventory!E:E,"",0,1))
A29: 16 | B29: 0 | C29: =Table1[[#This Row],[inventory_id_head]]&"-"&Table1[[#This Row],[inventory_id_tail]] -> 16-0 | D29: Active | E29: T003MF | F29: B005MF | G29: =E29&F29 -> T003MFB005MF | H29: driedflower_milled_bulk | J29: NA | K29: 44902 | L29: 1 | M29: bag | N29: =O29-P29 -> 132.02 | O29: 143.26 | P29: 11.24 | Q29: =L29*N29 -> 132.02 | R29: unknown lot | S29: 45484 | T29: gross | U29: =I29&"_"&H29 -> _driedflower_milled_bulk | V29: =IF(U29="_","",_xlfn.XLOOKUP(U29,internal_cansku_inventory!D:D,internal_cansku_inventory!E:E,"",0,1))
A30: 17 | B30: 0 | C30: =Table1[[#This Row],[inventory_id_head]]&"-"&Table1[[#This Row],[inventory_id_tail]] -> 17-0 | D30: Active | E30: T005DF | F30: B001DF | G30: =E30&F30 -> T005DFB001DF | H30: driedflower_packaged | J30: 2021022501 | K30: 45014 | L30: 37 | M30: bag | N30: 3.5 | O30: 0 | P30: 0 | Q30: =L30*N30 -> 129.5 | S30: 45484 | T30: net | U30: =I30&"_"&H30 -> _driedflower_packaged | V30: =IF(U30="_","",_xlfn.XLOOKUP(U30,internal_cansku_inventory!D:D,internal_cansku_inventory!E:E,"",0,1))
